2022-06-01 23:30:29,234 : WARNING : __main__ : TESTING TO SEE IF THIS IS RUN
2022-06-02 11:53:50,535 : WARNING : __main__ : TESTING TO SEE IF THIS IS RUN
2022-06-02 12:00:03,116 : WARNING : __main__ : TESTING TO SEE IF THIS IS RUN
2022-06-02 21:00:02,838 : WARNING : __main__ : TESTING TO SEE IF THIS IS RUN
2022-06-02 22:00:02,664 : WARNING : __main__ : TESTING TO SEE IF THIS IS RUN
2022-06-02 23:00:02,241 : WARNING : __main__ : TESTING TO SEE IF THIS IS RUN
2022-06-03 00:00:03,075 : WARNING : __main__ : TESTING TO SEE IF THIS IS RUN
2022-06-03 01:00:02,995 : WARNING : __main__ : TESTING TO SEE IF THIS IS RUN
2022-06-03 02:00:03,345 : WARNING : __main__ : TESTING TO SEE IF THIS IS RUN
2022-06-03 03:00:03,077 : WARNING : __main__ : TESTING TO SEE IF THIS IS RUN
2022-06-03 04:00:02,630 : WARNING : __main__ : TESTING TO SEE IF THIS IS RUN
2022-06-03 05:00:02,370 : WARNING : __main__ : TESTING TO SEE IF THIS IS RUN
2022-06-03 06:00:02,176 : WARNING : __main__ : TESTING TO SEE IF THIS IS RUN
2022-06-03 07:00:02,812 : WARNING : __main__ : TESTING TO SEE IF THIS IS RUN
2022-06-03 08:00:02,645 : WARNING : __main__ : TESTING TO SEE IF THIS IS RUN
2022-06-03 09:00:02,579 : WARNING : __main__ : TESTING TO SEE IF THIS IS RUN
2022-06-03 10:00:03,271 : WARNING : __main__ : TESTING TO SEE IF THIS IS RUN
2022-06-03 11:00:03,949 : WARNING : __main__ : TESTING TO SEE IF THIS IS RUN
2022-06-03 12:00:02,435 : WARNING : __main__ : TESTING TO SEE IF THIS IS RUN
2022-06-14 15:00:58,169 : ERROR : scraper_news.scraper : Module requests exception with url: https://shared.tv2.dk/t2breakingbar
Traceback (most recent call last):
  File "/usr/lib/python3/dist-packages/urllib3/connection.py", line 159, in _new_conn
    (self._dns_host, self.port), self.timeout, **extra_kw)
  File "/usr/lib/python3/dist-packages/urllib3/util/connection.py", line 57, in create_connection
    for res in socket.getaddrinfo(host, port, family, socket.SOCK_STREAM):
  File "/usr/lib/python3.7/socket.py", line 748, in getaddrinfo
    for res in _socket.getaddrinfo(host, port, family, type, proto, flags):
socket.gaierror: [Errno -3] Temporary failure in name resolution

During handling of the above exception, another exception occurred:

Traceback (most recent call last):
  File "/usr/lib/python3/dist-packages/urllib3/connectionpool.py", line 600, in urlopen
    chunked=chunked)
  File "/usr/lib/python3/dist-packages/urllib3/connectionpool.py", line 343, in _make_request
    self._validate_conn(conn)
  File "/usr/lib/python3/dist-packages/urllib3/connectionpool.py", line 841, in _validate_conn
    conn.connect()
  File "/usr/lib/python3/dist-packages/urllib3/connection.py", line 301, in connect
    conn = self._new_conn()
  File "/usr/lib/python3/dist-packages/urllib3/connection.py", line 168, in _new_conn
    self, "Failed to establish a new connection: %s" % e)
urllib3.exceptions.NewConnectionError: <urllib3.connection.VerifiedHTTPSConnection object at 0xb37075b0>: Failed to establish a new connection: [Errno -3] Temporary failure in name resolution

During handling of the above exception, another exception occurred:

Traceback (most recent call last):
  File "/home/pi/.local/lib/python3.7/site-packages/requests/adapters.py", line 449, in send
    timeout=timeout
  File "/usr/lib/python3/dist-packages/urllib3/connectionpool.py", line 638, in urlopen
    _stacktrace=sys.exc_info()[2])
  File "/usr/lib/python3/dist-packages/urllib3/util/retry.py", line 398, in increment
    raise MaxRetryError(_pool, url, error or ResponseError(cause))
urllib3.exceptions.MaxRetryError: HTTPSConnectionPool(host='shared.tv2.dk', port=443): Max retries exceeded with url: /t2breakingbar (Caused by NewConnectionError('<urllib3.connection.VerifiedHTTPSConnection object at 0xb37075b0>: Failed to establish a new connection: [Errno -3] Temporary failure in name resolution'))

During handling of the above exception, another exception occurred:

Traceback (most recent call last):
  File "/home/pi/Documents/scraper_news/scraper_news/scraper.py", line 76, in request_url
    response = requests.get(url, headers=REQUEST_HEADER, cookies=REQUEST_COOKIES, timeout=60)
  File "/home/pi/.local/lib/python3.7/site-packages/requests/api.py", line 76, in get
    return request('get', url, params=params, **kwargs)
  File "/home/pi/.local/lib/python3.7/site-packages/requests/api.py", line 61, in request
    return session.request(method=method, url=url, **kwargs)
  File "/home/pi/.local/lib/python3.7/site-packages/requests/sessions.py", line 530, in request
    resp = self.send(prep, **send_kwargs)
  File "/home/pi/.local/lib/python3.7/site-packages/requests/sessions.py", line 643, in send
    r = adapter.send(request, **kwargs)
  File "/home/pi/.local/lib/python3.7/site-packages/requests/adapters.py", line 516, in send
    raise ConnectionError(e, request=request)
requests.exceptions.ConnectionError: HTTPSConnectionPool(host='shared.tv2.dk', port=443): Max retries exceeded with url: /t2breakingbar (Caused by NewConnectionError('<urllib3.connection.VerifiedHTTPSConnection object at 0xb37075b0>: Failed to establish a new connection: [Errno -3] Temporary failure in name resolution'))
2022-06-14 16:00:18,850 : ERROR : scraper_news.scraper : Module requests exception with url: https://shared.tv2.dk/t2breakingbar
Traceback (most recent call last):
  File "/usr/lib/python3/dist-packages/urllib3/connection.py", line 159, in _new_conn
    (self._dns_host, self.port), self.timeout, **extra_kw)
  File "/usr/lib/python3/dist-packages/urllib3/util/connection.py", line 80, in create_connection
    raise err
  File "/usr/lib/python3/dist-packages/urllib3/util/connection.py", line 70, in create_connection
    sock.connect(sa)
OSError: [Errno 101] Network is unreachable

During handling of the above exception, another exception occurred:

Traceback (most recent call last):
  File "/usr/lib/python3/dist-packages/urllib3/connectionpool.py", line 600, in urlopen
    chunked=chunked)
  File "/usr/lib/python3/dist-packages/urllib3/connectionpool.py", line 343, in _make_request
    self._validate_conn(conn)
  File "/usr/lib/python3/dist-packages/urllib3/connectionpool.py", line 841, in _validate_conn
    conn.connect()
  File "/usr/lib/python3/dist-packages/urllib3/connection.py", line 301, in connect
    conn = self._new_conn()
  File "/usr/lib/python3/dist-packages/urllib3/connection.py", line 168, in _new_conn
    self, "Failed to establish a new connection: %s" % e)
urllib3.exceptions.NewConnectionError: <urllib3.connection.VerifiedHTTPSConnection object at 0xb36cc590>: Failed to establish a new connection: [Errno 101] Network is unreachable

During handling of the above exception, another exception occurred:

Traceback (most recent call last):
  File "/home/pi/.local/lib/python3.7/site-packages/requests/adapters.py", line 449, in send
    timeout=timeout
  File "/usr/lib/python3/dist-packages/urllib3/connectionpool.py", line 638, in urlopen
    _stacktrace=sys.exc_info()[2])
  File "/usr/lib/python3/dist-packages/urllib3/util/retry.py", line 398, in increment
    raise MaxRetryError(_pool, url, error or ResponseError(cause))
urllib3.exceptions.MaxRetryError: HTTPSConnectionPool(host='shared.tv2.dk', port=443): Max retries exceeded with url: /t2breakingbar (Caused by NewConnectionError('<urllib3.connection.VerifiedHTTPSConnection object at 0xb36cc590>: Failed to establish a new connection: [Errno 101] Network is unreachable'))

During handling of the above exception, another exception occurred:

Traceback (most recent call last):
  File "/home/pi/Documents/scraper_news/scraper_news/scraper.py", line 76, in request_url
    response = requests.get(url, headers=REQUEST_HEADER, cookies=REQUEST_COOKIES, timeout=60)
  File "/home/pi/.local/lib/python3.7/site-packages/requests/api.py", line 76, in get
    return request('get', url, params=params, **kwargs)
  File "/home/pi/.local/lib/python3.7/site-packages/requests/api.py", line 61, in request
    return session.request(method=method, url=url, **kwargs)
  File "/home/pi/.local/lib/python3.7/site-packages/requests/sessions.py", line 530, in request
    resp = self.send(prep, **send_kwargs)
  File "/home/pi/.local/lib/python3.7/site-packages/requests/sessions.py", line 643, in send
    r = adapter.send(request, **kwargs)
  File "/home/pi/.local/lib/python3.7/site-packages/requests/adapters.py", line 516, in send
    raise ConnectionError(e, request=request)
requests.exceptions.ConnectionError: HTTPSConnectionPool(host='shared.tv2.dk', port=443): Max retries exceeded with url: /t2breakingbar (Caused by NewConnectionError('<urllib3.connection.VerifiedHTTPSConnection object at 0xb36cc590>: Failed to establish a new connection: [Errno 101] Network is unreachable'))
2022-06-14 17:00:18,930 : ERROR : scraper_news.scraper : Module requests exception with url: https://shared.tv2.dk/t2breakingbar
Traceback (most recent call last):
  File "/usr/lib/python3/dist-packages/urllib3/connection.py", line 159, in _new_conn
    (self._dns_host, self.port), self.timeout, **extra_kw)
  File "/usr/lib/python3/dist-packages/urllib3/util/connection.py", line 80, in create_connection
    raise err
  File "/usr/lib/python3/dist-packages/urllib3/util/connection.py", line 70, in create_connection
    sock.connect(sa)
OSError: [Errno 101] Network is unreachable

During handling of the above exception, another exception occurred:

Traceback (most recent call last):
  File "/usr/lib/python3/dist-packages/urllib3/connectionpool.py", line 600, in urlopen
    chunked=chunked)
  File "/usr/lib/python3/dist-packages/urllib3/connectionpool.py", line 343, in _make_request
    self._validate_conn(conn)
  File "/usr/lib/python3/dist-packages/urllib3/connectionpool.py", line 841, in _validate_conn
    conn.connect()
  File "/usr/lib/python3/dist-packages/urllib3/connection.py", line 301, in connect
    conn = self._new_conn()
  File "/usr/lib/python3/dist-packages/urllib3/connection.py", line 168, in _new_conn
    self, "Failed to establish a new connection: %s" % e)
urllib3.exceptions.NewConnectionError: <urllib3.connection.VerifiedHTTPSConnection object at 0xb37225b0>: Failed to establish a new connection: [Errno 101] Network is unreachable

During handling of the above exception, another exception occurred:

Traceback (most recent call last):
  File "/home/pi/.local/lib/python3.7/site-packages/requests/adapters.py", line 449, in send
    timeout=timeout
  File "/usr/lib/python3/dist-packages/urllib3/connectionpool.py", line 638, in urlopen
    _stacktrace=sys.exc_info()[2])
  File "/usr/lib/python3/dist-packages/urllib3/util/retry.py", line 398, in increment
    raise MaxRetryError(_pool, url, error or ResponseError(cause))
urllib3.exceptions.MaxRetryError: HTTPSConnectionPool(host='shared.tv2.dk', port=443): Max retries exceeded with url: /t2breakingbar (Caused by NewConnectionError('<urllib3.connection.VerifiedHTTPSConnection object at 0xb37225b0>: Failed to establish a new connection: [Errno 101] Network is unreachable'))

During handling of the above exception, another exception occurred:

Traceback (most recent call last):
  File "/home/pi/Documents/scraper_news/scraper_news/scraper.py", line 76, in request_url
    response = requests.get(url, headers=REQUEST_HEADER, cookies=REQUEST_COOKIES, timeout=60)
  File "/home/pi/.local/lib/python3.7/site-packages/requests/api.py", line 76, in get
    return request('get', url, params=params, **kwargs)
  File "/home/pi/.local/lib/python3.7/site-packages/requests/api.py", line 61, in request
    return session.request(method=method, url=url, **kwargs)
  File "/home/pi/.local/lib/python3.7/site-packages/requests/sessions.py", line 530, in request
    resp = self.send(prep, **send_kwargs)
  File "/home/pi/.local/lib/python3.7/site-packages/requests/sessions.py", line 643, in send
    r = adapter.send(request, **kwargs)
  File "/home/pi/.local/lib/python3.7/site-packages/requests/adapters.py", line 516, in send
    raise ConnectionError(e, request=request)
requests.exceptions.ConnectionError: HTTPSConnectionPool(host='shared.tv2.dk', port=443): Max retries exceeded with url: /t2breakingbar (Caused by NewConnectionError('<urllib3.connection.VerifiedHTTPSConnection object at 0xb37225b0>: Failed to establish a new connection: [Errno 101] Network is unreachable'))
2022-06-14 18:00:18,050 : ERROR : scraper_news.scraper : Module requests exception with url: https://shared.tv2.dk/t2breakingbar
Traceback (most recent call last):
  File "/usr/lib/python3/dist-packages/urllib3/connection.py", line 159, in _new_conn
    (self._dns_host, self.port), self.timeout, **extra_kw)
  File "/usr/lib/python3/dist-packages/urllib3/util/connection.py", line 80, in create_connection
    raise err
  File "/usr/lib/python3/dist-packages/urllib3/util/connection.py", line 70, in create_connection
    sock.connect(sa)
OSError: [Errno 101] Network is unreachable

During handling of the above exception, another exception occurred:

Traceback (most recent call last):
  File "/usr/lib/python3/dist-packages/urllib3/connectionpool.py", line 600, in urlopen
    chunked=chunked)
  File "/usr/lib/python3/dist-packages/urllib3/connectionpool.py", line 343, in _make_request
    self._validate_conn(conn)
  File "/usr/lib/python3/dist-packages/urllib3/connectionpool.py", line 841, in _validate_conn
    conn.connect()
  File "/usr/lib/python3/dist-packages/urllib3/connection.py", line 301, in connect
    conn = self._new_conn()
  File "/usr/lib/python3/dist-packages/urllib3/connection.py", line 168, in _new_conn
    self, "Failed to establish a new connection: %s" % e)
urllib3.exceptions.NewConnectionError: <urllib3.connection.VerifiedHTTPSConnection object at 0xb36cc570>: Failed to establish a new connection: [Errno 101] Network is unreachable

During handling of the above exception, another exception occurred:

Traceback (most recent call last):
  File "/home/pi/.local/lib/python3.7/site-packages/requests/adapters.py", line 449, in send
    timeout=timeout
  File "/usr/lib/python3/dist-packages/urllib3/connectionpool.py", line 638, in urlopen
    _stacktrace=sys.exc_info()[2])
  File "/usr/lib/python3/dist-packages/urllib3/util/retry.py", line 398, in increment
    raise MaxRetryError(_pool, url, error or ResponseError(cause))
urllib3.exceptions.MaxRetryError: HTTPSConnectionPool(host='shared.tv2.dk', port=443): Max retries exceeded with url: /t2breakingbar (Caused by NewConnectionError('<urllib3.connection.VerifiedHTTPSConnection object at 0xb36cc570>: Failed to establish a new connection: [Errno 101] Network is unreachable'))

During handling of the above exception, another exception occurred:

Traceback (most recent call last):
  File "/home/pi/Documents/scraper_news/scraper_news/scraper.py", line 76, in request_url
    response = requests.get(url, headers=REQUEST_HEADER, cookies=REQUEST_COOKIES, timeout=60)
  File "/home/pi/.local/lib/python3.7/site-packages/requests/api.py", line 76, in get
    return request('get', url, params=params, **kwargs)
  File "/home/pi/.local/lib/python3.7/site-packages/requests/api.py", line 61, in request
    return session.request(method=method, url=url, **kwargs)
  File "/home/pi/.local/lib/python3.7/site-packages/requests/sessions.py", line 530, in request
    resp = self.send(prep, **send_kwargs)
  File "/home/pi/.local/lib/python3.7/site-packages/requests/sessions.py", line 643, in send
    r = adapter.send(request, **kwargs)
  File "/home/pi/.local/lib/python3.7/site-packages/requests/adapters.py", line 516, in send
    raise ConnectionError(e, request=request)
requests.exceptions.ConnectionError: HTTPSConnectionPool(host='shared.tv2.dk', port=443): Max retries exceeded with url: /t2breakingbar (Caused by NewConnectionError('<urllib3.connection.VerifiedHTTPSConnection object at 0xb36cc570>: Failed to establish a new connection: [Errno 101] Network is unreachable'))
2022-06-14 19:00:18,130 : ERROR : scraper_news.scraper : Module requests exception with url: https://shared.tv2.dk/t2breakingbar
Traceback (most recent call last):
  File "/usr/lib/python3/dist-packages/urllib3/connection.py", line 159, in _new_conn
    (self._dns_host, self.port), self.timeout, **extra_kw)
  File "/usr/lib/python3/dist-packages/urllib3/util/connection.py", line 80, in create_connection
    raise err
  File "/usr/lib/python3/dist-packages/urllib3/util/connection.py", line 70, in create_connection
    sock.connect(sa)
OSError: [Errno 101] Network is unreachable

During handling of the above exception, another exception occurred:

Traceback (most recent call last):
  File "/usr/lib/python3/dist-packages/urllib3/connectionpool.py", line 600, in urlopen
    chunked=chunked)
  File "/usr/lib/python3/dist-packages/urllib3/connectionpool.py", line 343, in _make_request
    self._validate_conn(conn)
  File "/usr/lib/python3/dist-packages/urllib3/connectionpool.py", line 841, in _validate_conn
    conn.connect()
  File "/usr/lib/python3/dist-packages/urllib3/connection.py", line 301, in connect
    conn = self._new_conn()
  File "/usr/lib/python3/dist-packages/urllib3/connection.py", line 168, in _new_conn
    self, "Failed to establish a new connection: %s" % e)
urllib3.exceptions.NewConnectionError: <urllib3.connection.VerifiedHTTPSConnection object at 0xb3765510>: Failed to establish a new connection: [Errno 101] Network is unreachable

During handling of the above exception, another exception occurred:

Traceback (most recent call last):
  File "/home/pi/.local/lib/python3.7/site-packages/requests/adapters.py", line 449, in send
    timeout=timeout
  File "/usr/lib/python3/dist-packages/urllib3/connectionpool.py", line 638, in urlopen
    _stacktrace=sys.exc_info()[2])
  File "/usr/lib/python3/dist-packages/urllib3/util/retry.py", line 398, in increment
    raise MaxRetryError(_pool, url, error or ResponseError(cause))
urllib3.exceptions.MaxRetryError: HTTPSConnectionPool(host='shared.tv2.dk', port=443): Max retries exceeded with url: /t2breakingbar (Caused by NewConnectionError('<urllib3.connection.VerifiedHTTPSConnection object at 0xb3765510>: Failed to establish a new connection: [Errno 101] Network is unreachable'))

During handling of the above exception, another exception occurred:

Traceback (most recent call last):
  File "/home/pi/Documents/scraper_news/scraper_news/scraper.py", line 76, in request_url
    response = requests.get(url, headers=REQUEST_HEADER, cookies=REQUEST_COOKIES, timeout=60)
  File "/home/pi/.local/lib/python3.7/site-packages/requests/api.py", line 76, in get
    return request('get', url, params=params, **kwargs)
  File "/home/pi/.local/lib/python3.7/site-packages/requests/api.py", line 61, in request
    return session.request(method=method, url=url, **kwargs)
  File "/home/pi/.local/lib/python3.7/site-packages/requests/sessions.py", line 530, in request
    resp = self.send(prep, **send_kwargs)
  File "/home/pi/.local/lib/python3.7/site-packages/requests/sessions.py", line 643, in send
    r = adapter.send(request, **kwargs)
  File "/home/pi/.local/lib/python3.7/site-packages/requests/adapters.py", line 516, in send
    raise ConnectionError(e, request=request)
requests.exceptions.ConnectionError: HTTPSConnectionPool(host='shared.tv2.dk', port=443): Max retries exceeded with url: /t2breakingbar (Caused by NewConnectionError('<urllib3.connection.VerifiedHTTPSConnection object at 0xb3765510>: Failed to establish a new connection: [Errno 101] Network is unreachable'))
2022-06-14 20:00:18,210 : ERROR : scraper_news.scraper : Module requests exception with url: https://shared.tv2.dk/t2breakingbar
Traceback (most recent call last):
  File "/usr/lib/python3/dist-packages/urllib3/connection.py", line 159, in _new_conn
    (self._dns_host, self.port), self.timeout, **extra_kw)
  File "/usr/lib/python3/dist-packages/urllib3/util/connection.py", line 80, in create_connection
    raise err
  File "/usr/lib/python3/dist-packages/urllib3/util/connection.py", line 70, in create_connection
    sock.connect(sa)
OSError: [Errno 101] Network is unreachable

During handling of the above exception, another exception occurred:

Traceback (most recent call last):
  File "/usr/lib/python3/dist-packages/urllib3/connectionpool.py", line 600, in urlopen
    chunked=chunked)
  File "/usr/lib/python3/dist-packages/urllib3/connectionpool.py", line 343, in _make_request
    self._validate_conn(conn)
  File "/usr/lib/python3/dist-packages/urllib3/connectionpool.py", line 841, in _validate_conn
    conn.connect()
  File "/usr/lib/python3/dist-packages/urllib3/connection.py", line 301, in connect
    conn = self._new_conn()
  File "/usr/lib/python3/dist-packages/urllib3/connection.py", line 168, in _new_conn
    self, "Failed to establish a new connection: %s" % e)
urllib3.exceptions.NewConnectionError: <urllib3.connection.VerifiedHTTPSConnection object at 0xb37733f0>: Failed to establish a new connection: [Errno 101] Network is unreachable

During handling of the above exception, another exception occurred:

Traceback (most recent call last):
  File "/home/pi/.local/lib/python3.7/site-packages/requests/adapters.py", line 449, in send
    timeout=timeout
  File "/usr/lib/python3/dist-packages/urllib3/connectionpool.py", line 638, in urlopen
    _stacktrace=sys.exc_info()[2])
  File "/usr/lib/python3/dist-packages/urllib3/util/retry.py", line 398, in increment
    raise MaxRetryError(_pool, url, error or ResponseError(cause))
urllib3.exceptions.MaxRetryError: HTTPSConnectionPool(host='shared.tv2.dk', port=443): Max retries exceeded with url: /t2breakingbar (Caused by NewConnectionError('<urllib3.connection.VerifiedHTTPSConnection object at 0xb37733f0>: Failed to establish a new connection: [Errno 101] Network is unreachable'))

During handling of the above exception, another exception occurred:

Traceback (most recent call last):
  File "/home/pi/Documents/scraper_news/scraper_news/scraper.py", line 76, in request_url
    response = requests.get(url, headers=REQUEST_HEADER, cookies=REQUEST_COOKIES, timeout=60)
  File "/home/pi/.local/lib/python3.7/site-packages/requests/api.py", line 76, in get
    return request('get', url, params=params, **kwargs)
  File "/home/pi/.local/lib/python3.7/site-packages/requests/api.py", line 61, in request
    return session.request(method=method, url=url, **kwargs)
  File "/home/pi/.local/lib/python3.7/site-packages/requests/sessions.py", line 530, in request
    resp = self.send(prep, **send_kwargs)
  File "/home/pi/.local/lib/python3.7/site-packages/requests/sessions.py", line 643, in send
    r = adapter.send(request, **kwargs)
  File "/home/pi/.local/lib/python3.7/site-packages/requests/adapters.py", line 516, in send
    raise ConnectionError(e, request=request)
requests.exceptions.ConnectionError: HTTPSConnectionPool(host='shared.tv2.dk', port=443): Max retries exceeded with url: /t2breakingbar (Caused by NewConnectionError('<urllib3.connection.VerifiedHTTPSConnection object at 0xb37733f0>: Failed to establish a new connection: [Errno 101] Network is unreachable'))
